Workbook

Sheet Inputs
A1: Inputs: given values and chosen design
A2: Blue = given in the assignment brief. Yellow = design choice (editable). Black = calculated.
A4: Quantity | B4: Value | C4: Unit | D4: Symbol in the mathematical model
A5: CSP plant (heliostat field, receiver, Rankine cycle)
A6: Mirror reflectivity | B6: 0.95 | C6: fraction | D6: Eff_reflectivity
A7: Average cosine efficiency | B7: 0.86 | C7: fraction | D7: Eff_cosine
A8: Shading and blocking efficiency | B8: 0.89 | C8: fraction | D8: Eff_shading blocking
A9: Atmospheric attenuation efficiency | B9: 0.97 | C9: fraction | D9: Eff_atmospheric
A10: Spillage efficiency | B10: 0.92 | C10: fraction | D10: Eff_spillage
A11: Receiver absorption efficiency | B11: 0.8 | C11: fraction | D11: Eff_receiver
A12: Rankine cycle thermal efficiency | B12: 0.42 | C12: fraction | D12: Eff_rankine
A13: Mirror area per heliostat | B13: 220 | C13: m² | D13: Area_per heliostat
A14: Heliostat cost per m² | B14: 80 | C14: EUR/m² | D14: Cost_CSP
A16: PVT panels (flat plate collector)
A17: PVT electrical efficiency | B17: 0.16 | C17: fraction | D17: Eff_PVT,elec
A18: Effective optical fraction (share of sunlight absorbed) | B18: 0.86 | C18: fraction | D18: Frac_absorbed
A19: Overall heat loss coefficient | B19: 12 | C19: W/(m²·K) | D19: Coef_heat loss
A20: Collector heat removal factor | B20: 0.65 | C20: fraction | D20: Factor_heat removal
A21: Inlet water temperature | B21: 35 | C21: °C | D21: T_water in
A22: Water flow rate through one PVT panel | B22: 0.2 | C22: kg/s | D22: FlowRate_per PVT panel
A23: Specific heat of water (standard value) | B23: 4186 | C23: J/(kg·K) | D23: c_p,water
A24: Area per PVT panel (2 m × 2 m) | B24: 4 | C24: m² | D24: Area_per PVT panel
A25: PVT cost per m² | B25: 150 | C25: EUR/m² | D25: Cost_PVT
A27: Site and rules
A28: Maximum available collector area | B28: 450000 | C28: m² | D28: Area_max
A29: Minimum share of electricity from CSP | B29: 0.6 | C29: fraction | D29: Share_CSP,min
A30: Degraded mirror reflectivity (Q7) | B30: 0.85 | C30: fraction | D30: –
A32: Unit conversions
A33: Energy of 1 W sustained for 1 hour | B33: 3.6e-06 | C33: GJ | D33: GJ_per W-hr
A35: Chosen design (cost optimum)
A36: Number of heliostats | B36: 215 | C36: units | D36: Count_heliostats
A37: Number of PVT panels | B37: 9559 | C37: units | D37: Count_PVT panels
A39: Calculated from the above
A40: Total mirror area | B40: =$B$36*$B$13 -> 47300 | C40: m² | D40: Area_CSP
A41: Total PVT area | B41: =$B$37*$B$24 -> 38236 | C41: m² | D41: Area_PVT
A42: Total collector area used | B42: =$B$40+$B$41 -> 85536 | C42: m²
A43: Optical efficiency of the heliostat field | B43: =$B$6*$B$7*$B$8*$B$9*$B$10 -> 0.64889081 | C43: fraction | D43: Eff_optical
A44: CSP efficiency, sunlight to electricity | B44: =$B$43*$B$11*$B$12 -> 0.21802731 | C44: fraction | D44: Eff_CSP
A45: CSP efficiency with degraded mirrors (Q7) | B45: =$B$30*$B$7*$B$8*$B$9*$B$10*$B$11*$B$12 -> 0.19507707 | C45: fraction | D45: –
A46: Cost of heliostats | B46: =$B$14*$B$40 -> 3784000 | C46: EUR
...

Sheet June hourly
A1: June 2019: hourly plant output and demand
A2: Design from the Inputs sheet. Supply and demand are energy delivered within each hour. Per-m² outputs are power.
A3: Hour of day | B3: Solar irradiance [W/m²] | C3: Ambient temperature [°C] | D3: Electricity demand [GJ] | E3: Heat demand [GJ] | F3: Sunlit hour [1 = yes] | G3: CSP electricity per m² of mirror [W/m²] | H3: PVT electricity per m² of panel [W/m²] | I3: PVT: sunlight absorbed [W/m²] | J3: PVT: convection loss [W/m²] | K3: PVT useful heat per m² of panel [W/m²] | L3: PVT water outlet temperature [°C] | M3: Electricity supplied by CSP [GJ] | N3: Electricity supplied by PVT [GJ] | O3: Total electricity supplied [GJ] | P3: Heat supplied by PVT [GJ] | Q3: Electricity surplus (+) or shortfall (−) [GJ] | R3: Heat surplus (+) or shortfall (−) [GJ] | S3: Q7: electricity by CSP, degraded mirrors [GJ] | T3: Q7: total electricity, degraded mirrors [GJ]
A4: 0 | B4: 0 | C4: 6.5 | D4: 4.9 | E4: 2.871 | F4: =IF(B4>0,1,0) -> 0 | G4: =Inputs!$B$44*B4 -> 0 | H4: =Inputs!$B$17*B4 -> 0 | I4: =Inputs!$B$18*B4 -> 0 | J4: =Inputs!$B$19*(Inputs!$B$21-C4) -> 342 | K4: =MAX(0,Inputs!$B$20*(I4-J4)) -> 0 | L4: =Inputs!$B$21+K4*Inputs!$B$24/(Inputs!$B$22*Inputs!$B$23) -> 35 | M4: =Inputs!$B$33*Inputs!$B$40*G4 -> 0 | N4: =Inputs!$B$33*Inputs!$B$41*H4 -> 0 | O4: =M4+N4 -> 0 | P4: =Inputs!$B$33*Inputs!$B$41*K4 -> 0 | Q4: =O4-D4 -> -4.9 | R4: =P4-E4 -> -2.871 | S4: =Inputs!$B$33*Inputs!$B$40*Inputs!$B$45*B4 -> 0 | T4: =S4+N4 -> 0
A5: 1 | B5: 0 | C5: 7 | D5: 2.9 | E5: 2.508 | F5: =IF(B5>0,1,0) -> 0 | G5: =Inputs!$B$44*B5 -> 0 | H5: =Inputs!$B$17*B5 -> 0 | I5: =Inputs!$B$18*B5 -> 0 | J5: =Inputs!$B$19*(Inputs!$B$21-C5) -> 336 | K5: =MAX(0,Inputs!$B$20*(I5-J5)) -> 0 | L5: =Inputs!$B$21+K5*Inputs!$B$24/(Inputs!$B$22*Inputs!$B$23) -> 35 | M5: =Inputs!$B$33*Inputs!$B$40*G5 -> 0 | N5: =Inputs!$B$33*Inputs!$B$41*H5 -> 0 | O5: =M5+N5 -> 0 | P5: =Inputs!$B$33*Inputs!$B$41*K5 -> 0 | Q5: =O5-D5 -> -2.9 | R5: =P5-E5 -> -2.508 | S5: =Inputs!$B$33*Inputs!$B$40*Inputs!$B$45*B5 -> 0 | T5: =S5+N5 -> 0
A6: 2 | B6: 0 | C6: 7 | D6: 2.4 | E6: 2.31 | F6: =IF(B6>0,1,0) -> 0 | G6: =Inputs!$B$44*B6 -> 0 | H6: =Inputs!$B$17*B6 -> 0 | I6: =Inputs!$B$18*B6 -> 0 | J6: =Inputs!$B$19*(Inputs!$B$21-C6) -> 336 | K6: =MAX(0,Inputs!$B$20*(I6-J6)) -> 0 | L6: =Inputs!$B$21+K6*Inputs!$B$24/(Inputs!$B$22*Inputs!$B$23) -> 35 | M6: =Inputs!$B$33*Inputs!$B$40*G6 -> 0 | N6: =Inputs!$B$33*Inputs!$B$41*H6 -> 0 | O6: =M6+N6 -> 0 | P6: =Inputs!$B$33*Inputs!$B$41*K6 -> 0 | Q6: =O6-D6 -> -2.4 | R6: =P6-E6 -> -2.31 | S6: =Inputs!$B$33*Inputs!$B$40*Inputs!$B$45*B6 -> 0 | T6: =S6+N6 -> 0
A7: 3 | B7: 0 | C7: 6 | D7: 1.9 | E7: 1.947 | F7: =IF(B7>0,1,0) -> 0 | G7: =Inputs!$B$44*B7 -> 0 | H7: =Inputs!$B$17*B7 -> 0 | I7: =Inputs!$B$18*B7 -> 0 | J7: =Inputs!$B$19*(Inputs!$B$21-C7) -> 348 | K7: =MAX(0,Inputs!$B$20*(I7-J7)) -> 0 | L7: =Inputs!$B$21+K7*Inputs!$B$24/(Inputs!$B$22*Inputs!$B$23) -> 35 | M7: =Inputs!$B$33*Inputs!$B$40*G7 -> 0 | N7: =Inputs!$B$33*Inputs!$B$41*H7 -> 0 | O7: =M7+N7 -> 0 | P7: =Inputs!$B$33*Inputs!$B$41*K7 -> 0 | Q7: =O7-D7 -> -1.9 | R7: =P7-E7 -> -1.947 | S7: =Inputs!$B$33*Inputs!$B$40*Inputs!$B$45*B7 -> 0 | T7: =S7+N7 -> 0
A8: 4 | B8: 0 | C8: 6 | D8: 1.6 | E8: 2.871 | F8: =IF(B8>0,1,0) -> 0 | G8: =Inputs!$B$44*B8 -> 0 | H8: =Inputs!$B$17*B8 -> 0 | I8: =Inputs!$B$18*B8 -> 0 | J8: =Inputs!$B$19*(Inputs!$B$21-C8) -> 348 | K8: =MAX(0,Inputs!$B$20*(I8-J8)) -> 0 | L8: =Inputs!$B$21+K8*Inputs!$B$24/(Inputs!$B$22*Inputs!$B$23) -> 35 | M8: =Inputs!$B$33*Inputs!$B$40*G8 -> 0 | N8: =Inputs!$B$33*Inputs!$B$41*H8 -> 0 | O8: =M8+N8 -> 0 | P8: =Inputs!$B$33*Inputs!$B$41*K8 -> 0 | Q8: =O8-D8 -> -1.6 | R8: =P8-E8 -> -2.871 | S8: =Inputs!$B$33*Inputs!$B$40*Inputs!$B$45*B8 -> 0 | T8: =S8+N8 -> 0
A9: 5 | B9: 0 | C9: 5 | D9: 2.7 | E9: 4.851 | F9: =IF(B9>0,1,0) -> 0 | G9: =Inputs!$B$44*B9 -> 0 | H9: =Inputs!$B$17*B9 -> 0 | I9: =Inputs!$B$18*B9 -> 0 | J9: =Inputs!$B$19*(Inputs!$B$21-C9) -> 360 | K9: =MAX(0,Inputs!$B$20*(I9-J9)) -> 0 | L9: =Inputs!$B$21+K9*Inputs!$B$24/(Inputs!$B$22*Inputs!$B$23) -> 35 | M9: =Inputs!$B$33*Inputs!$B$40*G9 -> 0 | N9: =Inputs!$B$33*Inputs!$B$41*H9 -> 0 | O9: =M9+N9 -> 0 | P9: =Inputs!$B$33*Inputs!$B$41*K9 -> 0 | Q9: =O9-D9 -> -2.7 | R9: =P9-E9 -> -4.851 | S9: =Inputs!$B$33*Inputs!$B$40*Inputs!$B$45*B9 -> 0 | T9: =S9+N9 -> 0
A10: 6 | B10: 0 | C10: 5 | D10: 6.2 | E10: 6.336 | F10: =IF(B10>0,1,0) -> 0 | G10: =Inputs!$B$44*B10 -> 0 | H10: =Inputs!$B$17*B10 -> 0 | I10: =Inputs!$B$18*B10 -> 0 | J10: =Inputs!$B$19*(Inputs!$B$21-C10) -> 360 | K10: =MAX(0,Inputs!$B$20*(I10-J10)) -> 0 | L10: =Inputs!$B$21+K10*Inputs!$B$24/(Inputs!$B$22*Inputs!$B$23) -> 35 | M10: =Inputs!$B$33*Inputs!$B$40*G10 -> 0 | N10: =Inputs!$B$33*Inputs!$B$41*H10 -> 0 | O10: =M10+N10 -> 0 | P10: =Inputs!$B$33*Inputs!$B$41*K10 -> 0 | Q10: =O10-D10 -> -6.2 | R10: =P10-E10 -> -6.336 | S10: =Inputs!$B$33*Inputs!$B$40*Inputs!$B$45*B10 -> 0 | T10: =S10+N10 -> 0
A11: 7 | B11: 114 | C11: 4 | D11: 14.8 | E11: 7.161 | F11: =IF(B11>0,1,0) -> 1 | G11: =Inputs!$B$44*B11 -> 24.855114 | H11: =Inputs!$B$17*B11 -> 18.24 | I11: =Inputs!$B$18*B11 -> 98.04 | J11: =Inputs!$B$19*(Inputs!$B$21-C11) -> 372 | K11: =MAX(0,Inputs!$B$20*(I11-J11)) -> 0 | L11: =Inputs!$B$21+K11*Inputs!$B$24/(Inputs!$B$22*Inputs!$B$23) -> 35 | M11: =Inputs!$B$33*Inputs!$B$40*G11 -> 4.2323288 | N11: =Inputs!$B$33*Inputs!$B$41*H11 -> 2.5107287 | O11: =M11+N11 -> 6.7430575 | P11: =Inputs!$B$33*Inputs!$B$41*K11 -> 0 | Q11: =O11-D11 -> -8.0569425 | R11: =P11-E11 -> -7.161 | S11: =Inputs!$B$33*Inputs!$B$40*Inputs!$B$45*B11 -> 3.7868205 | T11: =S11+N11 -> 6.2975492
A12: 8 | B12: 326 | C12: 5 | D12: 33.2 | E12: 7.722 | F12: =IF(B12>0,1,0) -> 1 | G12: =Inputs!$B$44*B12 -> 71.076904 | H12: =Inputs!$B$17*B12 -> 52.16 | I12: =Inputs!$B$18*B12 -> 280.36 | J12: =Inputs!$B$19*(Inputs!$B$21-C12) -> 360 | K12: =MAX(0,Inputs!$B$20*(I12-J12)) -> 0 | L12: =Inputs!$B$21+K12*Inputs!$B$24/(Inputs!$B$22*Inputs!$B$23) -> 35 | M12: =Inputs!$B$33*Inputs!$B$40*G12 -> 12.102975 | N12: =Inputs!$B$33*Inputs!$B$41*H12 -> 7.1798031 | O12: =M12+N12 -> 19.282778 | P12: =Inputs!$B$33*Inputs!$B$41*K12 -> 0 | Q12: =O12-D12 -> -13.917222 | R12: =P12-E12 -> -7.722 | S12: =Inputs!$B$33*Inputs!$B$40*Inputs!$B$45*B12 -> 10.828978 | T12: =S12+N12 -> 18.008781
A13: 9 | B13: 252 | C13: 6 | D13: 26.9 | E13: 9.108 | F13: =IF(B13>0,1,0) -> 1 | G13: =Inputs!$B$44*B13 -> 54.942883 | H13: =Inputs!$B$17*B13 -> 40.32 | I13: =Inputs!$B$18*B13 -> 216.72 | J13: =Inputs!$B$19*(Inputs!$B$21-C13) -> 348 | K13: =MAX(0,Inputs!$B$20*(I13-J13)) -> 0 | L13: =Inputs!$B$21+K13*Inputs!$B$24/(Inputs!$B$22*Inputs!$B$23) -> 35 | M13: =Inputs!$B$33*Inputs!$B$40*G13 -> 9.3556741 | N13: =Inputs!$B$33*Inputs!$B$41*H13 -> 5.5500319 | O13: =M13+N13 -> 14.905706 | P13: =Inputs!$B$33*Inputs!$B$41*K13 -> 0 | Q13: =O13-D13 -> -11.994294 | R13: =P13-E13 -> -9.108 | S13: =Inputs!$B$33*Inputs!$B$40*Inputs!$B$45*B13 -> 8.3708663 | T13: =S13+N13 -> 13.920898
A14: 10 | B14: 431 | C14: 8 | D14: 15.6 | E14: 11.022 | F14: =IF(B14>0,1,0) -> 1 | G14: =Inputs!$B$44*B14 -> 93.969772 | H14: =Inputs!$B$17*B14 -> 68.96 | I14: =Inputs!$B$18*B14 -> 370.66 | J14: =Inputs!$B$19*(Inputs!$B$21-C14) -> 324 | K14: =MAX(0,Inputs!$B$20*(I14-J14)) -> 30.329 | L14: =Inputs!$B$21+K14*Inputs!$B$24/(Inputs!$B$22*Inputs!$B$23) -> 35.144907 | M14: =Inputs!$B$33*Inputs!$B$40*G14 -> 16.001173 | N14: =Inputs!$B$33*Inputs!$B$41*H14 -> 9.4923164 | O14: =M14+N14 -> 25.493489 | P14: =Inputs!$B$33*Inputs!$B$41*K14 -> 4.1747747 | Q14: =O14-D14 -> 9.8934892 | R14: =P14-E14 -> -6.8472253 | S14: =Inputs!$B$33*Inputs!$B$40*Inputs!$B$45*B14 -> 14.316839 | T14: =S14+N14 -> 23.809155
A15: 11 | B15: 579 | C15: 11 | D15: 16.8 | E15: 11.517 | F15: =IF(B15>0,1,0) -> 1 | G15: =Inputs!$B$44*B15 -> 126.23781 | H15: =Inputs!$B$17*B15 -> 92.64 | I15: =Inputs!$B$18*B15 -> 497.94 | J15: =Inputs!$B$19*(Inputs!$B$21-C15) -> 288 | K15: =MAX(0,Inputs!$B$20*(I15-J15)) -> 136.461 | L15: =Inputs!$B$21+K15*Inputs!$B$24/(Inputs!$B$22*Inputs!$B$23) -> 35.651988 | M15: =Inputs!$B$33*Inputs!$B$40*G15 -> 21.495775 | N15: =Inputs!$B$33*Inputs!$B$41*H15 -> 12.751859 | O15: =M15+N15 -> 34.247634 | P15: =Inputs!$B$33*Inputs!$B$41*K15 -> 18.783802 | Q15: =O15-D15 -> 17.447634 | R15: =P15-E15 -> 7.2668021 | S15: =Inputs!$B$33*Inputs!$B$40*Inputs!$B$45*B15 -> 19.233062 | T15: =S15+N15 -> 31.984921
... A27: 23 | B27: 0 | C27: 6 | D27: 3.6 | E27: 9.867 | F27: =IF(B27>0,1,0) -> 0 | G27: =Inputs!$B$44*B27 -> 0 | H27: =Inputs!$B$17*B27 -> 0 | I27: =Inputs!$B$18*B27 -> 0 | J27: =Inputs!$B$19*(Inputs!$B$21-C27) -> 348 | K27: =MAX(0,Inputs!$B$20*(I27-J27)) -> 0 | L27: =Inputs!$B$21+K27*Inputs!$B$24/(Inputs!$B$22*Inputs!$B$23) -> 35 | M27: =Inputs!$B$33*Inputs!$B$40*G27 -> 0 | N27: =Inputs!$B$33*Inputs!$B$41*H27 -> 0 | O27: =M27+N27 -> 0 | P27: =Inputs!$B$33*Inputs!$B$41*K27 -> 0 | Q27: =O27-D27 -> -3.6 | R27: =P27-E27 -> -9.867 | S27: =Inputs!$B$33*Inputs!$B$40*Inputs!$B$45*B27 -> 0 | T27: =S27+N27 -> 0
A28: Day total | D28: =SUM(D4:D27) -> 438.3 | E28: =SUM(E4:E27) -> 237.468 | F28: =SUM(F4:F27) -> 14 | M28: =SUM(M4:M27) -> 226.46671 | N28: =SUM(N4:N27) -> 134.34601 | O28: =SUM(O4:O27) -> 360.81272 | P28: =SUM(P4:P27) -> 183.77598 | Q28: =SUM(Q4:Q27) -> -77.487276 | R28: =SUM(R4:R27) -> -53.692019 | S28: =SUM(S4:S27) -> 202.62811 | T28: =SUM(T4:T27) -> 336.97412
A29: Sunlit hours only | D29: =SUMPRODUCT(D4:D27,$F$4:$F$27) -> 360.8 | E29: =SUMPRODUCT(E4:E27,$F$4:$F$27) -> 183.579 | M29: =SUMPRODUCT(M4:M27,$F$4:$F$27) -> 226.46671 | N29: =SUMPRODUCT(N4:N27,$F$4:$F$27) -> 134.34601 | O29: =SUMPRODUCT(O4:O27,$F$4:$F$27) -> 360.81272 | P29: =SUMPRODUCT(P4:P27,$F$4:$F$27) -> 183.77598 | Q29: =SUMPRODUCT(Q4:Q27,$F$4:$F$27) -> 0.012723657 | R29: =SUMPRODUCT(R4:R27,$F$4:$F$27) -> 0.19698096 | S29: =SUMPRODUCT(S4:S27,$F$4:$F$27) -> 202.62811 | T29: =SUMPRODUCT(T4:T27,$F$4:$F$27) -> 336.97412

Sheet December hourly
A1: December 2019: hourly plant output and demand
A2: Design from the Inputs sheet. Supply and demand are energy delivered within each hour. Per-m² outputs are power.
A3: Hour of day | B3: Solar irradiance [W/m²] | C3: Ambient temperature [°C] | D3: Electricity demand [GJ] | E3: Heat demand [GJ] | F3: Sunlit hour [1 = yes] | G3: CSP electricity per m² of mirror [W/m²] | H3: PVT electricity per m² of panel [W/m²] | I3: PVT: sunlight absorbed [W/m²] | J3: PVT: convection loss [W/m²] | K3: PVT useful heat per m² of panel [W/m²] | L3: PVT water outlet temperature [°C] | M3: Electricity supplied by CSP [GJ] | N3: Electricity supplied by PVT [GJ] | O3: Total electricity supplied [GJ] | P3: Heat supplied by PVT [GJ] | Q3: Electricity surplus (+) or shortfall (−) [GJ] | R3: Heat surplus (+) or shortfall (−) [GJ] | S3: Q7: electricity by CSP, degraded mirrors [GJ] | T3: Q7: total electricity, degraded mirrors [GJ]
A4: 0 | B4: 0 | C4: 16.666667 | D4: 7.3 | E4: 2.0493 | F4: =IF(B4>0,1,0) -> 0 | G4: =Inputs!$B$44*B4 -> 0 | H4: =Inputs!$B$17*B4 -> 0 | I4: =Inputs!$B$18*B4 -> 0 | J4: =Inputs!$B$19*(Inputs!$B$21-C4) -> 220 | K4: =MAX(0,Inputs!$B$20*(I4-J4)) -> 0 | L4: =Inputs!$B$21+K4*Inputs!$B$24/(Inputs!$B$22*Inputs!$B$23) -> 35 | M4: =Inputs!$B$33*Inputs!$B$40*G4 -> 0 | N4: =Inputs!$B$33*Inputs!$B$41*H4 -> 0 | O4: =M4+N4 -> 0 | P4: =Inputs!$B$33*Inputs!$B$41*K4 -> 0 | Q4: =O4-D4 -> -7.3 | R4: =P4-E4 -> -2.0493 | S4: =Inputs!$B$33*Inputs!$B$40*Inputs!$B$45*B4 -> 0 | T4: =S4+N4 -> 0
A5: 1 | B5: 0 | C5: 16.111111 | D5: 5.3 | E5: 1.6863 | F5: =IF(B5>0,1,0) -> 0 | G5: =Inputs!$B$44*B5 -> 0 | H5: =Inputs!$B$17*B5 -> 0 | I5: =Inputs!$B$18*B5 -> 0 | J5: =Inputs!$B$19*(Inputs!$B$21-C5) -> 226.66667 | K5: =MAX(0,Inputs!$B$20*(I5-J5)) -> 0 | L5: =Inputs!$B$21+K5*Inputs!$B$24/(Inputs!$B$22*Inputs!$B$23) -> 35 | M5: =Inputs!$B$33*Inputs!$B$40*G5 -> 0 | N5: =Inputs!$B$33*Inputs!$B$41*H5 -> 0 | O5: =M5+N5 -> 0 | P5: =Inputs!$B$33*Inputs!$B$41*K5 -> 0 | Q5: =O5-D5 -> -5.3 | R5: =P5-E5 -> -1.6863 | S5: =Inputs!$B$33*Inputs!$B$40*Inputs!$B$45*B5 -> 0 | T5: =S5+N5 -> 0
A6: 2 | B6: 0 | C6: 15.555556 | D6: 4.8 | E6: 1.4883 | F6: =IF(B6>0,1,0) -> 0 | G6: =Inputs!$B$44*B6 -> 0 | H6: =Inputs!$B$17*B6 -> 0 | I6: =Inputs!$B$18*B6 -> 0 | J6: =Inputs!$B$19*(Inputs!$B$21-C6) -> 233.33333 | K6: =MAX(0,Inputs!$B$20*(I6-J6)) -> 0 | L6: =Inputs!$B$21+K6*Inputs!$B$24/(Inputs!$B$22*Inputs!$B$23) -> 35 | M6: =Inputs!$B$33*Inputs!$B$40*G6 -> 0 | N6: =Inputs!$B$33*Inputs!$B$41*H6 -> 0 | O6: =M6+N6 -> 0 | P6: =Inputs!$B$33*Inputs!$B$41*K6 -> 0 | Q6: =O6-D6 -> -4.8 | R6: =P6-E6 -> -1.4883 | S6: =Inputs!$B$33*Inputs!$B$40*Inputs!$B$45*B6 -> 0 | T6: =S6+N6 -> 0
A7: 3 | B7: 0 | C7: 15 | D7: 4.3 | E7: 1.1253 | F7: =IF(B7>0,1,0) -> 0 | G7: =Inputs!$B$44*B7 -> 0 | H7: =Inputs!$B$17*B7 -> 0 | I7: =Inputs!$B$18*B7 -> 0 | J7: =Inputs!$B$19*(Inputs!$B$21-C7) -> 240 | K7: =MAX(0,Inputs!$B$20*(I7-J7)) -> 0 | L7: =Inputs!$B$21+K7*Inputs!$B$24/(Inputs!$B$22*Inputs!$B$23) -> 35 | M7: =Inputs!$B$33*Inputs!$B$40*G7 -> 0 | N7: =Inputs!$B$33*Inputs!$B$41*H7 -> 0 | O7: =M7+N7 -> 0 | P7: =Inputs!$B$33*Inputs!$B$41*K7 -> 0 | Q7: =O7-D7 -> -4.3 | R7: =P7-E7 -> -1.1253 | S7: =Inputs!$B$33*Inputs!$B$40*Inputs!$B$45*B7 -> 0 | T7: =S7+N7 -> 0
A8: 4 | B8: 0 | C8: 13.888889 | D8: 4 | E8: 2.0493 | F8: =IF(B8>0,1,0) -> 0 | G8: =Inputs!$B$44*B8 -> 0 | H8: =Inputs!$B$17*B8 -> 0 | I8: =Inputs!$B$18*B8 -> 0 | J8: =Inputs!$B$19*(Inputs!$B$21-C8) -> 253.33333 | K8: =MAX(0,Inputs!$B$20*(I8-J8)) -> 0 | L8: =Inputs!$B$21+K8*Inputs!$B$24/(Inputs!$B$22*Inputs!$B$23) -> 35 | M8: =Inputs!$B$33*Inputs!$B$40*G8 -> 0 | N8: =Inputs!$B$33*Inputs!$B$41*H8 -> 0 | O8: =M8+N8 -> 0 | P8: =Inputs!$B$33*Inputs!$B$41*K8 -> 0 | Q8: =O8-D8 -> -4 | R8: =P8-E8 -> -2.0493 | S8: =Inputs!$B$33*Inputs!$B$40*Inputs!$B$45*B8 -> 0 | T8: =S8+N8 -> 0
A9: 5 | B9: 0 | C9: 13.333333 | D9: 5.1 | E9: 4.0293 | F9: =IF(B9>0,1,0) -> 0 | G9: =Inputs!$B$44*B9 -> 0 | H9: =Inputs!$B$17*B9 -> 0 | I9: =Inputs!$B$18*B9 -> 0 | J9: =Inputs!$B$19*(Inputs!$B$21-C9) -> 260 | K9: =MAX(0,Inputs!$B$20*(I9-J9)) -> 0 | L9: =Inputs!$B$21+K9*Inputs!$B$24/(Inputs!$B$22*Inputs!$B$23) -> 35 | M9: =Inputs!$B$33*Inputs!$B$40*G9 -> 0 | N9: =Inputs!$B$33*Inputs!$B$41*H9 -> 0 | O9: =M9+N9 -> 0 | P9: =Inputs!$B$33*Inputs!$B$41*K9 -> 0 | Q9: =O9-D9 -> -5.1 | R9: =P9-E9 -> -4.0293 | S9: =Inputs!$B$33*Inputs!$B$40*Inputs!$B$45*B9 -> 0 | T9: =S9+N9 -> 0
A10: 6 | B10: 100 | C10: 12.777778 | D10: 10.1 | E10: 5.5143 | F10: =IF(B10>0,1,0) -> 1 | G10: =Inputs!$B$44*B10 -> 21.802731 | H10: =Inputs!$B$17*B10 -> 16 | I10: =Inputs!$B$18*B10 -> 86 | J10: =Inputs!$B$19*(Inputs!$B$21-C10) -> 266.66667 | K10: =MAX(0,Inputs!$B$20*(I10-J10)) -> 0 | L10: =Inputs!$B$21+K10*Inputs!$B$24/(Inputs!$B$22*Inputs!$B$23) -> 35 | M10: =Inputs!$B$33*Inputs!$B$40*G10 -> 3.7125691 | N10: =Inputs!$B$33*Inputs!$B$41*H10 -> 2.2023936 | O10: =M10+N10 -> 5.9149627 | P10: =Inputs!$B$33*Inputs!$B$41*K10 -> 0 | Q10: =O10-D10 -> -4.1850373 | R10: =P10-E10 -> -5.5143 | S10: =Inputs!$B$33*Inputs!$B$40*Inputs!$B$45*B10 -> 3.3217723 | T10: =S10+N10 -> 5.5241659
A11: 7 | B11: 128 | C11: 13.888889 | D11: 18.7 | E11: 6.3393 | F11: =IF(B11>0,1,0) -> 1 | G11: =Inputs!$B$44*B11 -> 27.907496 | H11: =Inputs!$B$17*B11 -> 20.48 | I11: =Inputs!$B$18*B11 -> 110.08 | J11: =Inputs!$B$19*(Inputs!$B$21-C11) -> 253.33333 | K11: =MAX(0,Inputs!$B$20*(I11-J11)) -> 0 | L11: =Inputs!$B$21+K11*Inputs!$B$24/(Inputs!$B$22*Inputs!$B$23) -> 35 | M11: =Inputs!$B$33*Inputs!$B$40*G11 -> 4.7520884 | N11: =Inputs!$B$33*Inputs!$B$41*H11 -> 2.8190638 | O11: =M11+N11 -> 7.5711522 | P11: =Inputs!$B$33*Inputs!$B$41*K11 -> 0 | Q11: =O11-D11 -> -11.128848 | R11: =P11-E11 -> -6.3393 | S11: =Inputs!$B$33*Inputs!$B$40*Inputs!$B$45*B11 -> 4.2518686 | T11: =S11+N11 -> 7.0709324
A12: 8 | B12: 395 | C12: 15.555556 | D12: 37.1 | E12: 6.9003 | F12: =IF(B12>0,1,0) -> 1 | G12: =Inputs!$B$44*B12 -> 86.120789 | H12: =Inputs!$B$17*B12 -> 63.2 | I12: =Inputs!$B$18*B12 -> 339.7 | J12: =Inputs!$B$19*(Inputs!$B$21-C12) -> 233.33333 | K12: =MAX(0,Inputs!$B$20*(I12-J12)) -> 69.138333 | L12: =Inputs!$B$21+K12*Inputs!$B$24/(Inputs!$B$22*Inputs!$B$23) -> 35.330331 | M12: =Inputs!$B$33*Inputs!$B$40*G12 -> 14.664648 | N12: =Inputs!$B$33*Inputs!$B$41*H12 -> 8.6994547 | O12: =M12+N12 -> 23.364103 | P12: =Inputs!$B$33*Inputs!$B$41*K12 -> 9.5168639 | Q12: =O12-D12 -> -13.735897 | R12: =P12-E12 -> 2.6165639 | S12: =Inputs!$B$33*Inputs!$B$40*Inputs!$B$45*B12 -> 13.121001 | T12: =S12+N12 -> 21.820455
A13: 9 | B13: 562 | C13: 18.333333 | D13: 30.8 | E13: 8.2863 | F13: =IF(B13>0,1,0) -> 1 | G13: =Inputs!$B$44*B13 -> 122.53135 | H13: =Inputs!$B$17*B13 -> 89.92 | I13: =Inputs!$B$18*B13 -> 483.32 | J13: =Inputs!$B$19*(Inputs!$B$21-C13) -> 200 | K13: =MAX(0,Inputs!$B$20*(I13-J13)) -> 184.158 | L13: =Inputs!$B$21+K13*Inputs!$B$24/(Inputs!$B$22*Inputs!$B$23) -> 35.879876 | M13: =Inputs!$B$33*Inputs!$B$40*G13 -> 20.864638 | N13: =Inputs!$B$33*Inputs!$B$41*H13 -> 12.377452 | O13: =M13+N13 -> 33.24209 | P13: =Inputs!$B$33*Inputs!$B$41*K13 -> 25.349275 | Q13: =O13-D13 -> 2.4420903 | R13: =P13-E13 -> 17.062975 | S13: =Inputs!$B$33*Inputs!$B$40*Inputs!$B$45*B13 -> 18.668361 | T13: =S13+N13 -> 31.045813
A14: 10 | B14: 729 | C14: 21.666667 | D14: 19.5 | E14: 10.2003 | F14: =IF(B14>0,1,0) -> 1 | G14: =Inputs!$B$44*B14 -> 158.94191 | H14: =Inputs!$B$17*B14 -> 116.64 | I14: =Inputs!$B$18*B14 -> 626.94 | J14: =Inputs!$B$19*(Inputs!$B$21-C14) -> 160 | K14: =MAX(0,Inputs!$B$20*(I14-J14)) -> 303.511 | L14: =Inputs!$B$21+K14*Inputs!$B$24/(Inputs!$B$22*Inputs!$B$23) -> 36.450124 | M14: =Inputs!$B$33*Inputs!$B$40*G14 -> 27.064629 | N14: =Inputs!$B$33*Inputs!$B$41*H14 -> 16.055449 | O14: =M14+N14 -> 43.120078 | P14: =Inputs!$B$33*Inputs!$B$41*K14 -> 41.778168 | Q14: =O14-D14 -> 23.620078 | R14: =P14-E14 -> 31.577868 | S14: =Inputs!$B$33*Inputs!$B$40*Inputs!$B$45*B14 -> 24.21572 | T14: =S14+N14 -> 40.27117
A15: 11 | B15: 912 | C15: 23.333333 | D15: 20.7 | E15: 10.6953 | F15: =IF(B15>0,1,0) -> 1 | G15: =Inputs!$B$44*B15 -> 198.84091 | H15: =Inputs!$B$17*B15 -> 145.92 | I15: =Inputs!$B$18*B15 -> 784.32 | J15: =Inputs!$B$19*(Inputs!$B$21-C15) -> 140 | K15: =MAX(0,Inputs!$B$20*(I15-J15)) -> 418.808 | L15: =Inputs!$B$21+K15*Inputs!$B$24/(Inputs!$B$22*Inputs!$B$23) -> 37.000994 | M15: =Inputs!$B$33*Inputs!$B$40*G15 -> 33.85863 | N15: =Inputs!$B$33*Inputs!$B$41*H15 -> 20.08583 | O15: =M15+N15 -> 53.94446 | P15: =Inputs!$B$33*Inputs!$B$41*K15 -> 57.648754 | Q15: =O15-D15 -> 33.24446 | R15: =P15-E15 -> 46.953454 | S15: =Inputs!$B$33*Inputs!$B$40*Inputs!$B$45*B15 -> 30.294564 | T15: =S15+N15 -> 50.380393
... A27: 23 | B27: 0 | C27: 19.444444 | D27: 9.4 | E27: 1.947 | F27: =IF(B27>0,1,0) -> 0 | G27: =Inputs!$B$44*B27 -> 0 | H27: =Inputs!$B$17*B27 -> 0 | I27: =Inputs!$B$18*B27 -> 0 | J27: =Inputs!$B$19*(Inputs!$B$21-C27) -> 186.66667 | K27: =MAX(0,Inputs!$B$20*(I27-J27)) -> 0 | L27: =Inputs!$B$21+K27*Inputs!$B$24/(Inputs!$B$22*Inputs!$B$23) -> 35 | M27: =Inputs!$B$33*Inputs!$B$40*G27 -> 0 | N27: =Inputs!$B$33*Inputs!$B$41*H27 -> 0 | O27: =M27+N27 -> 0 | P27: =Inputs!$B$33*Inputs!$B$41*K27 -> 0 | Q27: =O27-D27 -> -9.4 | R27: =P27-E27 -> -1.947 | S27: =Inputs!$B$33*Inputs!$B$40*Inputs!$B$45*B27 -> 0 | T27: =S27+N27 -> 0
A28: Day total | D28: =SUM(D4:D27) -> 541.9 | E28: =SUM(E4:E27) -> 152.8659 | F28: =SUM(F4:F27) -> 16 | M28: =SUM(M4:M27) -> 329.15637 | N28: =SUM(N4:N27) -> 195.26422 | O28: =SUM(O4:O27) -> 524.42059 | P28: =SUM(P4:P27) -> 509.96433 | Q28: =SUM(Q4:Q27) -> -17.479409 | R28: =SUM(R4:R27) -> 357.09843 | S28: =SUM(S4:S27) -> 294.50834 | T28: =SUM(T4:T27) -> 489.77255
A29: Sunlit hours only | D29: =SUMPRODUCT(D4:D27,$F$4:$F$27) -> 478.4 | E29: =SUMPRODUCT(E4:E27,$F$4:$F$27) -> 136.5771 | M29: =SUMPRODUCT(M4:M27,$F$4:$F$27) -> 329.15637 | N29: =SUMPRODUCT(N4:N27,$F$4:$F$27) -> 195.26422 | O29: =SUMPRODUCT(O4:O27,$F$4:$F$27) -> 524.42059 | P29: =SUMPRODUCT(P4:P27,$F$4:$F$27) -> 509.96433 | Q29: =SUMPRODUCT(Q4:Q27,$F$4:$F$27) -> 46.020591 | R29: =SUMPRODUCT(R4:R27,$F$4:$F$27) -> 373.38723 | S29: =SUMPRODUCT(S4:S27,$F$4:$F$27) -> 294.50834 | T29: =SUMPRODUCT(T4:T27,$F$4:$F$27) -> 489.77255

Sheet Cost sweep
A1: Cost sweep: cheapest number of heliostats for each number of PVT panels
A2: Data behind the design-space figure. Values calculated by the script. The highlighted row is the cost optimum.
A3: Number of PVT panels | B3: Fewest heliostats meeting electricity demand and 60% CSP share (both days) | C3: Heat demand met on both days | D3: Design feasible | E3: Total cost [EUR]
A4: 0 | B4: 343 | C4: no | D4: no | E4: 6036800
A5: 100 | B5: 342 | C5: no | D5: no | E5: 6079200
A6: 200 | B6: 340 | C6: no | D6: no | E6: 6104000
A7: 300 | B7: 339 | C7: no | D7: no | E7: 6146400
A8: 400 | B8: 338 | C8: no | D8: no | E8: 6188800
A9: 500 | B9: 336 | C9: no | D9: no | E9: 6213600
A10: 600 | B10: 335 | C10: no | D10: no | E10: 6256000
A11: 700 | B11: 334 | C11: no | D11: no | E11: 6298400
A12: 800 | B12: 332 | C12: no | D12: no | E12: 6323200
A13: 900 | B13: 331 | C13: no | D13: no | E13: 6365600
A14: 1000 | B14: 330 | C14: no | D14: no | E14: 6408000
A15: 1100 | B15: 328 | C15: no | D15: no | E15: 6432800
... A292: 28700 | B292: 575 | C292: yes | D292: yes | E292: 27340000
